Item(by='vimy', descendants=None, kids=[25606531], score=None, time=1609531916, title=None, item_type='comment', url=None, parent=25606473, text='Sorry, that was the wrong error.<p>&quot;[2021-01-01 21:06:27,366] ERROR in app: Exception on &#x2F; [GET]\nTraceback (most recent call last):<p><pre><code>  File &quot;flask&#x2F;app.py&quot;, line 2447, in wsgi_app\n\n  File &quot;flask&#x2F;app.py&quot;, line 1952, in full_dispatch_request\n\n  File &quot;flask&#x2F;app.py&quot;, line 1821, in handle_user_exception\n\n  File &quot;flask&#x2F;_compat.py&quot;, line 39, in reraise\n\n  File &quot;flask&#x2F;app.py&quot;, line 1950, in full_dispatch_request\n\n  File &quot;flask&#x2F;app.py&quot;, line 1936, in dispatch_request\n\n  File &quot;imessage2020wrapped&#x2F;app.py&quot;, line 360, in index\n\n  File &quot;imessage2020wrapped&#x2F;app.py&quot;, line 194, in get_when_data\n\n  File &quot;imessage2020wrapped&#x2F;app.py&quot;, line 155, in avg_datetime\n&quot;</code></pre>')